2020-07-06 22:36:45 [scrapy.utils.log] INFO: Scrapy 2.1.0 started (bot: movies)
2020-07-06 22:36:45 [scrapy.utils.log] INFO: Versions: lxml 4.5.0.0, libxml2 2.9.10, cssselect 1.1.0, parsel 1.6.0, w3lib 1.22.0, Twisted 20.3.0, Python 3.7.6 (v3.7.6:43364a7ae0, Dec 18 2019, 14:18:50) - [Clang 6.0 (clang-600.0.57)], pyOpenSSL 19.1.0 (OpenSSL 1.1.1g  21 Apr 2020), cryptography 2.9.2, Platform Darwin-19.5.0-x86_64-i386-64bit
2020-07-06 22:36:45 [scrapy.utils.log] DEBUG: Using reactor: twisted.internet.selectreactor.SelectReactor
2020-07-06 22:36:45 [scrapy.crawler] INFO: Overridden settings:
{'BOT_NAME': 'movies',
 'DOWNLOAD_DELAY': 0.5,
 'DOWNLOAD_TIMEOUT': 5,
 'DOWNLOAD_WARNSIZE': 0,
 'LOG_FILE': 'log/scrapy_log_20200706_223645.log',
 'NEWSPIDER_MODULE': 'movies.spiders',
 'SPIDER_MODULES': ['movies.spiders'],
 'USER_AGENT': 'Mozilla/5.0 (Macintosh; Intel Mac OS X 10_15_1) '
               'AppleWebKit/537.36 (KHTML, like Gecko) Chrome/83.0.4103.116 '
               'Safari/537.36'}
2020-07-06 22:36:45 [scrapy.extensions.telnet] INFO: Telnet Password: 86625f3c3d500210
2020-07-06 22:36:45 [scrapy.middleware] INFO: Enabled extensions:
['scrapy.extensions.corestats.CoreStats',
 'scrapy.extensions.telnet.TelnetConsole',
 'scrapy.extensions.memusage.MemoryUsage',
 'scrapy.extensions.logstats.LogStats']
2020-07-06 22:36:45 [scrapy.middleware] INFO: Enabled downloader middlewares:
['scrapy.downloadermiddlewares.httpauth.HttpAuthMiddleware',
 'scrapy.downloadermiddlewares.downloadtimeout.DownloadTimeoutMiddleware',
 'scrapy.downloadermiddlewares.defaultheaders.DefaultHeadersMiddleware',
 'movies.middlewares.RandomHttpProxyMiddleware',
 'scrapy.downloadermiddlewares.useragent.UserAgentMiddleware',
 'movies.middlewares.MoviesDownloaderMiddleware',
 'scrapy.downloadermiddlewares.retry.RetryMiddleware',
 'scrapy.downloadermiddlewares.redirect.MetaRefreshMiddleware',
 'scrapy.downloadermiddlewares.httpcompression.HttpCompressionMiddleware',
 'scrapy.downloadermiddlewares.redirect.RedirectMiddleware',
 'scrapy.downloadermiddlewares.cookies.CookiesMiddleware',
 'scrapy.downloadermiddlewares.httpproxy.HttpProxyMiddleware',
 'scrapy.downloadermiddlewares.stats.DownloaderStats']
2020-07-06 22:36:45 [scrapy.middleware] INFO: Enabled spider middlewares:
['scrapy.spidermiddlewares.httperror.HttpErrorMiddleware',
 'scrapy.spidermiddlewares.offsite.OffsiteMiddleware',
 'scrapy.spidermiddlewares.referer.RefererMiddleware',
 'scrapy.spidermiddlewares.urllength.UrlLengthMiddleware',
 'scrapy.spidermiddlewares.depth.DepthMiddleware']
2020-07-06 22:36:45 [scrapy.middleware] INFO: Enabled item pipelines:
['movies.pipelines.MoviesPipeline']
2020-07-06 22:36:45 [scrapy.core.engine] INFO: Spider opened
2020-07-06 22:36:45 [scrapy.extensions.logstats] INFO: Crawled 0 pages (at 0 pages/min), scraped 0 items (at 0 items/min)
2020-07-06 22:36:45 [maoyan] INFO: Spider opened: maoyan
2020-07-06 22:36:45 [scrapy.extensions.telnet] INFO: Telnet console listening on 127.0.0.1:6023
2020-07-06 22:36:46 [scrapy.core.engine] DEBUG: Crawled (200) <GET https://maoyan.com/films?showType=3> (referer: https://maoyan.com/films?showType=3)
2020-07-06 22:36:46 [scrapy.core.scraper] ERROR: Error processing {'movie_name': '天气之子', 'movie_time': '2019-11-01', 'movie_type': '爱情／动画／奇幻'}
Traceback (most recent call last):
  File "/Users/zhangzhuoyu 1/homework/Python001-class01/week02/作业一/movies/movies/pipelines.py", line 50, in process_item
    self.cursor.execute(sql)
  File "/Library/Frameworks/Python.framework/Versions/3.7/lib/python3.7/site-packages/pymysql/cursors.py", line 170, in execute
    result = self._query(query)
  File "/Library/Frameworks/Python.framework/Versions/3.7/lib/python3.7/site-packages/pymysql/cursors.py", line 328, in _query
    conn.query(q)
  File "/Library/Frameworks/Python.framework/Versions/3.7/lib/python3.7/site-packages/pymysql/connections.py", line 517, in query
    self._affected_rows = self._read_query_result(unbuffered=unbuffered)
  File "/Library/Frameworks/Python.framework/Versions/3.7/lib/python3.7/site-packages/pymysql/connections.py", line 732, in _read_query_result
    result.read()
  File "/Library/Frameworks/Python.framework/Versions/3.7/lib/python3.7/site-packages/pymysql/connections.py", line 1075, in read
    first_packet = self.connection._read_packet()
  File "/Library/Frameworks/Python.framework/Versions/3.7/lib/python3.7/site-packages/pymysql/connections.py", line 684, in _read_packet
    packet.check_error()
  File "/Library/Frameworks/Python.framework/Versions/3.7/lib/python3.7/site-packages/pymysql/protocol.py", line 220, in check_error
    err.raise_mysql_exception(self._data)
  File "/Library/Frameworks/Python.framework/Versions/3.7/lib/python3.7/site-packages/pymysql/err.py", line 109, in raise_mysql_exception
    raise errorclass(errno, errval)
pymysql.err.InternalError: (1054, "Unknown column 'name' in 'field list'")

During handling of the above exception, another exception occurred:

Traceback (most recent call last):
  File "/Library/Frameworks/Python.framework/Versions/3.7/lib/python3.7/site-packages/twisted/internet/defer.py", line 654, in _runCallbacks
    current.result = callback(current.result, *args, **kw)
  File "/Library/Frameworks/Python.framework/Versions/3.7/lib/python3.7/site-packages/scrapy/utils/defer.py", line 154, in f
    return deferred_from_coro(coro_f(*coro_args, **coro_kwargs))
  File "/Users/zhangzhuoyu 1/homework/Python001-class01/week02/作业一/movies/movies/pipelines.py", line 55, in process_item
    self.logger.error(e)
AttributeError: 'MoviesPipeline' object has no attribute 'logger'
2020-07-06 22:36:46 [scrapy.core.scraper] ERROR: Error processing {'movie_name': '误杀', 'movie_time': '2019-12-13', 'movie_type': '剧情／犯罪'}
Traceback (most recent call last):
  File "/Users/zhangzhuoyu 1/homework/Python001-class01/week02/作业一/movies/movies/pipelines.py", line 50, in process_item
    self.cursor.execute(sql)
  File "/Library/Frameworks/Python.framework/Versions/3.7/lib/python3.7/site-packages/pymysql/cursors.py", line 170, in execute
    result = self._query(query)
  File "/Library/Frameworks/Python.framework/Versions/3.7/lib/python3.7/site-packages/pymysql/cursors.py", line 328, in _query
    conn.query(q)
  File "/Library/Frameworks/Python.framework/Versions/3.7/lib/python3.7/site-packages/pymysql/connections.py", line 517, in query
    self._affected_rows = self._read_query_result(unbuffered=unbuffered)
  File "/Library/Frameworks/Python.framework/Versions/3.7/lib/python3.7/site-packages/pymysql/connections.py", line 732, in _read_query_result
    result.read()
  File "/Library/Frameworks/Python.framework/Versions/3.7/lib/python3.7/site-packages/pymysql/connections.py", line 1075, in read
    first_packet = self.connection._read_packet()
  File "/Library/Frameworks/Python.framework/Versions/3.7/lib/python3.7/site-packages/pymysql/connections.py", line 684, in _read_packet
    packet.check_error()
  File "/Library/Frameworks/Python.framework/Versions/3.7/lib/python3.7/site-packages/pymysql/protocol.py", line 220, in check_error
    err.raise_mysql_exception(self._data)
  File "/Library/Frameworks/Python.framework/Versions/3.7/lib/python3.7/site-packages/pymysql/err.py", line 109, in raise_mysql_exception
    raise errorclass(errno, errval)
pymysql.err.InternalError: (1054, "Unknown column 'name' in 'field list'")

During handling of the above exception, another exception occurred:

Traceback (most recent call last):
  File "/Library/Frameworks/Python.framework/Versions/3.7/lib/python3.7/site-packages/twisted/internet/defer.py", line 654, in _runCallbacks
    current.result = callback(current.result, *args, **kw)
  File "/Library/Frameworks/Python.framework/Versions/3.7/lib/python3.7/site-packages/scrapy/utils/defer.py", line 154, in f
    return deferred_from_coro(coro_f(*coro_args, **coro_kwargs))
  File "/Users/zhangzhuoyu 1/homework/Python001-class01/week02/作业一/movies/movies/pipelines.py", line 55, in process_item
    self.logger.error(e)
AttributeError: 'MoviesPipeline' object has no attribute 'logger'
2020-07-06 22:36:46 [scrapy.core.scraper] ERROR: Error processing {'movie_name': '唐人街探案2', 'movie_time': '2018-02-16', 'movie_type': '喜剧／动作／悬疑'}
Traceback (most recent call last):
  File "/Users/zhangzhuoyu 1/homework/Python001-class01/week02/作业一/movies/movies/pipelines.py", line 50, in process_item
    self.cursor.execute(sql)
  File "/Library/Frameworks/Python.framework/Versions/3.7/lib/python3.7/site-packages/pymysql/cursors.py", line 170, in execute
    result = self._query(query)
  File "/Library/Frameworks/Python.framework/Versions/3.7/lib/python3.7/site-packages/pymysql/cursors.py", line 328, in _query
    conn.query(q)
  File "/Library/Frameworks/Python.framework/Versions/3.7/lib/python3.7/site-packages/pymysql/connections.py", line 517, in query
    self._affected_rows = self._read_query_result(unbuffered=unbuffered)
  File "/Library/Frameworks/Python.framework/Versions/3.7/lib/python3.7/site-packages/pymysql/connections.py", line 732, in _read_query_result
    result.read()
  File "/Library/Frameworks/Python.framework/Versions/3.7/lib/python3.7/site-packages/pymysql/connections.py", line 1075, in read
    first_packet = self.connection._read_packet()
  File "/Library/Frameworks/Python.framework/Versions/3.7/lib/python3.7/site-packages/pymysql/connections.py", line 684, in _read_packet
    packet.check_error()
  File "/Library/Frameworks/Python.framework/Versions/3.7/lib/python3.7/site-packages/pymysql/protocol.py", line 220, in check_error
    err.raise_mysql_exception(self._data)
  File "/Library/Frameworks/Python.framework/Versions/3.7/lib/python3.7/site-packages/pymysql/err.py", line 109, in raise_mysql_exception
    raise errorclass(errno, errval)
pymysql.err.InternalError: (1054, "Unknown column 'name' in 'field list'")

During handling of the above exception, another exception occurred:

Traceback (most recent call last):
  File "/Library/Frameworks/Python.framework/Versions/3.7/lib/python3.7/site-packages/twisted/internet/defer.py", line 654, in _runCallbacks
    current.result = callback(current.result, *args, **kw)
  File "/Library/Frameworks/Python.framework/Versions/3.7/lib/python3.7/site-packages/scrapy/utils/defer.py", line 154, in f
    return deferred_from_coro(coro_f(*coro_args, **coro_kwargs))
  File "/Users/zhangzhuoyu 1/homework/Python001-class01/week02/作业一/movies/movies/pipelines.py", line 55, in process_item
    self.logger.error(e)
AttributeError: 'MoviesPipeline' object has no attribute 'logger'
2020-07-06 22:36:46 [scrapy.core.scraper] ERROR: Error processing {'movie_name': '活着', 'movie_time': '2020-06-24', 'movie_type': '灾难'}
Traceback (most recent call last):
  File "/Users/zhangzhuoyu 1/homework/Python001-class01/week02/作业一/movies/movies/pipelines.py", line 50, in process_item
    self.cursor.execute(sql)
  File "/Library/Frameworks/Python.framework/Versions/3.7/lib/python3.7/site-packages/pymysql/cursors.py", line 170, in execute
    result = self._query(query)
  File "/Library/Frameworks/Python.framework/Versions/3.7/lib/python3.7/site-packages/pymysql/cursors.py", line 328, in _query
    conn.query(q)
  File "/Library/Frameworks/Python.framework/Versions/3.7/lib/python3.7/site-packages/pymysql/connections.py", line 517, in query
    self._affected_rows = self._read_query_result(unbuffered=unbuffered)
  File "/Library/Frameworks/Python.framework/Versions/3.7/lib/python3.7/site-packages/pymysql/connections.py", line 732, in _read_query_result
    result.read()
  File "/Library/Frameworks/Python.framework/Versions/3.7/lib/python3.7/site-packages/pymysql/connections.py", line 1075, in read
    first_packet = self.connection._read_packet()
  File "/Library/Frameworks/Python.framework/Versions/3.7/lib/python3.7/site-packages/pymysql/connections.py", line 684, in _read_packet
    packet.check_error()
  File "/Library/Frameworks/Python.framework/Versions/3.7/lib/python3.7/site-packages/pymysql/protocol.py", line 220, in check_error
    err.raise_mysql_exception(self._data)
  File "/Library/Frameworks/Python.framework/Versions/3.7/lib/python3.7/site-packages/pymysql/err.py", line 109, in raise_mysql_exception
    raise errorclass(errno, errval)
pymysql.err.InternalError: (1054, "Unknown column 'name' in 'field list'")

During handling of the above exception, another exception occurred:

Traceback (most recent call last):
  File "/Library/Frameworks/Python.framework/Versions/3.7/lib/python3.7/site-packages/twisted/internet/defer.py", line 654, in _runCallbacks
    current.result = callback(current.result, *args, **kw)
  File "/Library/Frameworks/Python.framework/Versions/3.7/lib/python3.7/site-packages/scrapy/utils/defer.py", line 154, in f
    return deferred_from_coro(coro_f(*coro_args, **coro_kwargs))
  File "/Users/zhangzhuoyu 1/homework/Python001-class01/week02/作业一/movies/movies/pipelines.py", line 55, in process_item
    self.logger.error(e)
AttributeError: 'MoviesPipeline' object has no attribute 'logger'
2020-07-06 22:36:46 [scrapy.core.scraper] ERROR: Error processing {'movie_name': '哪吒之魔童降世', 'movie_time': '2019-07-26', 'movie_type': '动画／喜剧／奇幻'}
Traceback (most recent call last):
  File "/Users/zhangzhuoyu 1/homework/Python001-class01/week02/作业一/movies/movies/pipelines.py", line 50, in process_item
    self.cursor.execute(sql)
  File "/Library/Frameworks/Python.framework/Versions/3.7/lib/python3.7/site-packages/pymysql/cursors.py", line 170, in execute
    result = self._query(query)
  File "/Library/Frameworks/Python.framework/Versions/3.7/lib/python3.7/site-packages/pymysql/cursors.py", line 328, in _query
    conn.query(q)
  File "/Library/Frameworks/Python.framework/Versions/3.7/lib/python3.7/site-packages/pymysql/connections.py", line 517, in query
    self._affected_rows = self._read_query_result(unbuffered=unbuffered)
  File "/Library/Frameworks/Python.framework/Versions/3.7/lib/python3.7/site-packages/pymysql/connections.py", line 732, in _read_query_result
    result.read()
  File "/Library/Frameworks/Python.framework/Versions/3.7/lib/python3.7/site-packages/pymysql/connections.py", line 1075, in read
    first_packet = self.connection._read_packet()
  File "/Library/Frameworks/Python.framework/Versions/3.7/lib/python3.7/site-packages/pymysql/connections.py", line 684, in _read_packet
    packet.check_error()
  File "/Library/Frameworks/Python.framework/Versions/3.7/lib/python3.7/site-packages/pymysql/protocol.py", line 220, in check_error
    err.raise_mysql_exception(self._data)
  File "/Library/Frameworks/Python.framework/Versions/3.7/lib/python3.7/site-packages/pymysql/err.py", line 109, in raise_mysql_exception
    raise errorclass(errno, errval)
pymysql.err.InternalError: (1054, "Unknown column 'name' in 'field list'")

During handling of the above exception, another exception occurred:

Traceback (most recent call last):
  File "/Library/Frameworks/Python.framework/Versions/3.7/lib/python3.7/site-packages/twisted/internet/defer.py", line 654, in _runCallbacks
    current.result = callback(current.result, *args, **kw)
  File "/Library/Frameworks/Python.framework/Versions/3.7/lib/python3.7/site-packages/scrapy/utils/defer.py", line 154, in f
    return deferred_from_coro(coro_f(*coro_args, **coro_kwargs))
  File "/Users/zhangzhuoyu 1/homework/Python001-class01/week02/作业一/movies/movies/pipelines.py", line 55, in process_item
    self.logger.error(e)
AttributeError: 'MoviesPipeline' object has no attribute 'logger'
2020-07-06 22:36:46 [scrapy.core.scraper] ERROR: Error processing {'movie_name': '少年的你', 'movie_time': '2019-10-25', 'movie_type': '爱情／青春／剧情'}
Traceback (most recent call last):
  File "/Users/zhangzhuoyu 1/homework/Python001-class01/week02/作业一/movies/movies/pipelines.py", line 50, in process_item
    self.cursor.execute(sql)
  File "/Library/Frameworks/Python.framework/Versions/3.7/lib/python3.7/site-packages/pymysql/cursors.py", line 170, in execute
    result = self._query(query)
  File "/Library/Frameworks/Python.framework/Versions/3.7/lib/python3.7/site-packages/pymysql/cursors.py", line 328, in _query
    conn.query(q)
  File "/Library/Frameworks/Python.framework/Versions/3.7/lib/python3.7/site-packages/pymysql/connections.py", line 517, in query
    self._affected_rows = self._read_query_result(unbuffered=unbuffered)
  File "/Library/Frameworks/Python.framework/Versions/3.7/lib/python3.7/site-packages/pymysql/connections.py", line 732, in _read_query_result
    result.read()
  File "/Library/Frameworks/Python.framework/Versions/3.7/lib/python3.7/site-packages/pymysql/connections.py", line 1075, in read
    first_packet = self.connection._read_packet()
  File "/Library/Frameworks/Python.framework/Versions/3.7/lib/python3.7/site-packages/pymysql/connections.py", line 684, in _read_packet
    packet.check_error()
  File "/Library/Frameworks/Python.framework/Versions/3.7/lib/python3.7/site-packages/pymysql/protocol.py", line 220, in check_error
    err.raise_mysql_exception(self._data)
  File "/Library/Frameworks/Python.framework/Versions/3.7/lib/python3.7/site-packages/pymysql/err.py", line 109, in raise_mysql_exception
    raise errorclass(errno, errval)
pymysql.err.InternalError: (1054, "Unknown column 'name' in 'field list'")

During handling of the above exception, another exception occurred:

Traceback (most recent call last):
  File "/Library/Frameworks/Python.framework/Versions/3.7/lib/python3.7/site-packages/twisted/internet/defer.py", line 654, in _runCallbacks
    current.result = callback(current.result, *args, **kw)
  File "/Library/Frameworks/Python.framework/Versions/3.7/lib/python3.7/site-packages/scrapy/utils/defer.py", line 154, in f
    return deferred_from_coro(coro_f(*coro_args, **coro_kwargs))
  File "/Users/zhangzhuoyu 1/homework/Python001-class01/week02/作业一/movies/movies/pipelines.py", line 55, in process_item
    self.logger.error(e)
AttributeError: 'MoviesPipeline' object has no attribute 'logger'
2020-07-06 22:36:46 [scrapy.core.scraper] ERROR: Error processing {'movie_name': '战狼2', 'movie_time': '2017-07-27', 'movie_type': '动作／战争'}
Traceback (most recent call last):
  File "/Users/zhangzhuoyu 1/homework/Python001-class01/week02/作业一/movies/movies/pipelines.py", line 50, in process_item
    self.cursor.execute(sql)
  File "/Library/Frameworks/Python.framework/Versions/3.7/lib/python3.7/site-packages/pymysql/cursors.py", line 170, in execute
    result = self._query(query)
  File "/Library/Frameworks/Python.framework/Versions/3.7/lib/python3.7/site-packages/pymysql/cursors.py", line 328, in _query
    conn.query(q)
  File "/Library/Frameworks/Python.framework/Versions/3.7/lib/python3.7/site-packages/pymysql/connections.py", line 517, in query
    self._affected_rows = self._read_query_result(unbuffered=unbuffered)
  File "/Library/Frameworks/Python.framework/Versions/3.7/lib/python3.7/site-packages/pymysql/connections.py", line 732, in _read_query_result
    result.read()
  File "/Library/Frameworks/Python.framework/Versions/3.7/lib/python3.7/site-packages/pymysql/connections.py", line 1075, in read
    first_packet = self.connection._read_packet()
  File "/Library/Frameworks/Python.framework/Versions/3.7/lib/python3.7/site-packages/pymysql/connections.py", line 684, in _read_packet
    packet.check_error()
  File "/Library/Frameworks/Python.framework/Versions/3.7/lib/python3.7/site-packages/pymysql/protocol.py", line 220, in check_error
    err.raise_mysql_exception(self._data)
  File "/Library/Frameworks/Python.framework/Versions/3.7/lib/python3.7/site-packages/pymysql/err.py", line 109, in raise_mysql_exception
    raise errorclass(errno, errval)
pymysql.err.InternalError: (1054, "Unknown column 'name' in 'field list'")

During handling of the above exception, another exception occurred:

Traceback (most recent call last):
  File "/Library/Frameworks/Python.framework/Versions/3.7/lib/python3.7/site-packages/twisted/internet/defer.py", line 654, in _runCallbacks
    current.result = callback(current.result, *args, **kw)
  File "/Library/Frameworks/Python.framework/Versions/3.7/lib/python3.7/site-packages/scrapy/utils/defer.py", line 154, in f
    return deferred_from_coro(coro_f(*coro_args, **coro_kwargs))
  File "/Users/zhangzhuoyu 1/homework/Python001-class01/week02/作业一/movies/movies/pipelines.py", line 55, in process_item
    self.logger.error(e)
AttributeError: 'MoviesPipeline' object has no attribute 'logger'
2020-07-06 22:36:46 [scrapy.core.scraper] ERROR: Error processing {'movie_name': '毒液2', 'movie_time': '2020-06-25', 'movie_type': '动作／科幻／惊悚／恐怖'}
Traceback (most recent call last):
  File "/Users/zhangzhuoyu 1/homework/Python001-class01/week02/作业一/movies/movies/pipelines.py", line 50, in process_item
    self.cursor.execute(sql)
  File "/Library/Frameworks/Python.framework/Versions/3.7/lib/python3.7/site-packages/pymysql/cursors.py", line 170, in execute
    result = self._query(query)
  File "/Library/Frameworks/Python.framework/Versions/3.7/lib/python3.7/site-packages/pymysql/cursors.py", line 328, in _query
    conn.query(q)
  File "/Library/Frameworks/Python.framework/Versions/3.7/lib/python3.7/site-packages/pymysql/connections.py", line 517, in query
    self._affected_rows = self._read_query_result(unbuffered=unbuffered)
  File "/Library/Frameworks/Python.framework/Versions/3.7/lib/python3.7/site-packages/pymysql/connections.py", line 732, in _read_query_result
    result.read()
  File "/Library/Frameworks/Python.framework/Versions/3.7/lib/python3.7/site-packages/pymysql/connections.py", line 1075, in read
    first_packet = self.connection._read_packet()
  File "/Library/Frameworks/Python.framework/Versions/3.7/lib/python3.7/site-packages/pymysql/connections.py", line 684, in _read_packet
    packet.check_error()
  File "/Library/Frameworks/Python.framework/Versions/3.7/lib/python3.7/site-packages/pymysql/protocol.py", line 220, in check_error
    err.raise_mysql_exception(self._data)
  File "/Library/Frameworks/Python.framework/Versions/3.7/lib/python3.7/site-packages/pymysql/err.py", line 109, in raise_mysql_exception
    raise errorclass(errno, errval)
pymysql.err.InternalError: (1054, "Unknown column 'name' in 'field list'")

During handling of the above exception, another exception occurred:

Traceback (most recent call last):
  File "/Library/Frameworks/Python.framework/Versions/3.7/lib/python3.7/site-packages/twisted/internet/defer.py", line 654, in _runCallbacks
    current.result = callback(current.result, *args, **kw)
  File "/Library/Frameworks/Python.framework/Versions/3.7/lib/python3.7/site-packages/scrapy/utils/defer.py", line 154, in f
    return deferred_from_coro(coro_f(*coro_args, **coro_kwargs))
  File "/Users/zhangzhuoyu 1/homework/Python001-class01/week02/作业一/movies/movies/pipelines.py", line 55, in process_item
    self.logger.error(e)
AttributeError: 'MoviesPipeline' object has no attribute 'logger'
2020-07-06 22:36:46 [scrapy.core.scraper] ERROR: Error processing {'movie_name': '恐怖电影院2', 'movie_time': '2017-10-20', 'movie_type': '恐怖／惊悚'}
Traceback (most recent call last):
  File "/Users/zhangzhuoyu 1/homework/Python001-class01/week02/作业一/movies/movies/pipelines.py", line 50, in process_item
    self.cursor.execute(sql)
  File "/Library/Frameworks/Python.framework/Versions/3.7/lib/python3.7/site-packages/pymysql/cursors.py", line 170, in execute
    result = self._query(query)
  File "/Library/Frameworks/Python.framework/Versions/3.7/lib/python3.7/site-packages/pymysql/cursors.py", line 328, in _query
    conn.query(q)
  File "/Library/Frameworks/Python.framework/Versions/3.7/lib/python3.7/site-packages/pymysql/connections.py", line 517, in query
    self._affected_rows = self._read_query_result(unbuffered=unbuffered)
  File "/Library/Frameworks/Python.framework/Versions/3.7/lib/python3.7/site-packages/pymysql/connections.py", line 732, in _read_query_result
    result.read()
  File "/Library/Frameworks/Python.framework/Versions/3.7/lib/python3.7/site-packages/pymysql/connections.py", line 1075, in read
    first_packet = self.connection._read_packet()
  File "/Library/Frameworks/Python.framework/Versions/3.7/lib/python3.7/site-packages/pymysql/connections.py", line 684, in _read_packet
    packet.check_error()
  File "/Library/Frameworks/Python.framework/Versions/3.7/lib/python3.7/site-packages/pymysql/protocol.py", line 220, in check_error
    err.raise_mysql_exception(self._data)
  File "/Library/Frameworks/Python.framework/Versions/3.7/lib/python3.7/site-packages/pymysql/err.py", line 109, in raise_mysql_exception
    raise errorclass(errno, errval)
pymysql.err.InternalError: (1054, "Unknown column 'name' in 'field list'")

During handling of the above exception, another exception occurred:

Traceback (most recent call last):
  File "/Library/Frameworks/Python.framework/Versions/3.7/lib/python3.7/site-packages/twisted/internet/defer.py", line 654, in _runCallbacks
    current.result = callback(current.result, *args, **kw)
  File "/Library/Frameworks/Python.framework/Versions/3.7/lib/python3.7/site-packages/scrapy/utils/defer.py", line 154, in f
    return deferred_from_coro(coro_f(*coro_args, **coro_kwargs))
  File "/Users/zhangzhuoyu 1/homework/Python001-class01/week02/作业一/movies/movies/pipelines.py", line 55, in process_item
    self.logger.error(e)
AttributeError: 'MoviesPipeline' object has no attribute 'logger'
2020-07-06 22:36:46 [scrapy.core.scraper] ERROR: Error processing {'movie_name': '哥斯拉2：怪兽之王',
 'movie_time': '2019-05-31',
 'movie_type': '科幻／灾难／动作'}
Traceback (most recent call last):
  File "/Users/zhangzhuoyu 1/homework/Python001-class01/week02/作业一/movies/movies/pipelines.py", line 50, in process_item
    self.cursor.execute(sql)
  File "/Library/Frameworks/Python.framework/Versions/3.7/lib/python3.7/site-packages/pymysql/cursors.py", line 170, in execute
    result = self._query(query)
  File "/Library/Frameworks/Python.framework/Versions/3.7/lib/python3.7/site-packages/pymysql/cursors.py", line 328, in _query
    conn.query(q)
  File "/Library/Frameworks/Python.framework/Versions/3.7/lib/python3.7/site-packages/pymysql/connections.py", line 517, in query
    self._affected_rows = self._read_query_result(unbuffered=unbuffered)
  File "/Library/Frameworks/Python.framework/Versions/3.7/lib/python3.7/site-packages/pymysql/connections.py", line 732, in _read_query_result
    result.read()
  File "/Library/Frameworks/Python.framework/Versions/3.7/lib/python3.7/site-packages/pymysql/connections.py", line 1075, in read
    first_packet = self.connection._read_packet()
  File "/Library/Frameworks/Python.framework/Versions/3.7/lib/python3.7/site-packages/pymysql/connections.py", line 684, in _read_packet
    packet.check_error()
  File "/Library/Frameworks/Python.framework/Versions/3.7/lib/python3.7/site-packages/pymysql/protocol.py", line 220, in check_error
    err.raise_mysql_exception(self._data)
  File "/Library/Frameworks/Python.framework/Versions/3.7/lib/python3.7/site-packages/pymysql/err.py", line 109, in raise_mysql_exception
    raise errorclass(errno, errval)
pymysql.err.InternalError: (1054, "Unknown column 'name' in 'field list'")

During handling of the above exception, another exception occurred:

Traceback (most recent call last):
  File "/Library/Frameworks/Python.framework/Versions/3.7/lib/python3.7/site-packages/twisted/internet/defer.py", line 654, in _runCallbacks
    current.result = callback(current.result, *args, **kw)
  File "/Library/Frameworks/Python.framework/Versions/3.7/lib/python3.7/site-packages/scrapy/utils/defer.py", line 154, in f
    return deferred_from_coro(coro_f(*coro_args, **coro_kwargs))
  File "/Users/zhangzhuoyu 1/homework/Python001-class01/week02/作业一/movies/movies/pipelines.py", line 55, in process_item
    self.logger.error(e)
AttributeError: 'MoviesPipeline' object has no attribute 'logger'
2020-07-06 22:36:46 [scrapy.core.scraper] ERROR: Error processing {'movie_name': '复仇者联盟4：终局之战',
 'movie_time': '2019-04-24',
 'movie_type': '动作／冒险／奇幻'}
Traceback (most recent call last):
  File "/Users/zhangzhuoyu 1/homework/Python001-class01/week02/作业一/movies/movies/pipelines.py", line 50, in process_item
    self.cursor.execute(sql)
  File "/Library/Frameworks/Python.framework/Versions/3.7/lib/python3.7/site-packages/pymysql/cursors.py", line 170, in execute
    result = self._query(query)
  File "/Library/Frameworks/Python.framework/Versions/3.7/lib/python3.7/site-packages/pymysql/cursors.py", line 328, in _query
    conn.query(q)
  File "/Library/Frameworks/Python.framework/Versions/3.7/lib/python3.7/site-packages/pymysql/connections.py", line 517, in query
    self._affected_rows = self._read_query_result(unbuffered=unbuffered)
  File "/Library/Frameworks/Python.framework/Versions/3.7/lib/python3.7/site-packages/pymysql/connections.py", line 732, in _read_query_result
    result.read()
  File "/Library/Frameworks/Python.framework/Versions/3.7/lib/python3.7/site-packages/pymysql/connections.py", line 1075, in read
    first_packet = self.connection._read_packet()
  File "/Library/Frameworks/Python.framework/Versions/3.7/lib/python3.7/site-packages/pymysql/connections.py", line 684, in _read_packet
    packet.check_error()
  File "/Library/Frameworks/Python.framework/Versions/3.7/lib/python3.7/site-packages/pymysql/protocol.py", line 220, in check_error
    err.raise_mysql_exception(self._data)
  File "/Library/Frameworks/Python.framework/Versions/3.7/lib/python3.7/site-packages/pymysql/err.py", line 109, in raise_mysql_exception
    raise errorclass(errno, errval)
pymysql.err.InternalError: (1054, "Unknown column 'name' in 'field list'")

During handling of the above exception, another exception occurred:

Traceback (most recent call last):
  File "/Library/Frameworks/Python.framework/Versions/3.7/lib/python3.7/site-packages/twisted/internet/defer.py", line 654, in _runCallbacks
    current.result = callback(current.result, *args, **kw)
  File "/Library/Frameworks/Python.framework/Versions/3.7/lib/python3.7/site-packages/scrapy/utils/defer.py", line 154, in f
    return deferred_from_coro(coro_f(*coro_args, **coro_kwargs))
  File "/Users/zhangzhuoyu 1/homework/Python001-class01/week02/作业一/movies/movies/pipelines.py", line 55, in process_item
    self.logger.error(e)
AttributeError: 'MoviesPipeline' object has no attribute 'logger'
2020-07-06 22:36:46 [scrapy.core.scraper] ERROR: Error processing {'movie_name': '野性的呼唤', 'movie_time': '2020-02-21', 'movie_type': '剧情／冒险'}
Traceback (most recent call last):
  File "/Users/zhangzhuoyu 1/homework/Python001-class01/week02/作业一/movies/movies/pipelines.py", line 50, in process_item
    self.cursor.execute(sql)
  File "/Library/Frameworks/Python.framework/Versions/3.7/lib/python3.7/site-packages/pymysql/cursors.py", line 170, in execute
    result = self._query(query)
  File "/Library/Frameworks/Python.framework/Versions/3.7/lib/python3.7/site-packages/pymysql/cursors.py", line 328, in _query
    conn.query(q)
  File "/Library/Frameworks/Python.framework/Versions/3.7/lib/python3.7/site-packages/pymysql/connections.py", line 517, in query
    self._affected_rows = self._read_query_result(unbuffered=unbuffered)
  File "/Library/Frameworks/Python.framework/Versions/3.7/lib/python3.7/site-packages/pymysql/connections.py", line 732, in _read_query_result
    result.read()
  File "/Library/Frameworks/Python.framework/Versions/3.7/lib/python3.7/site-packages/pymysql/connections.py", line 1075, in read
    first_packet = self.connection._read_packet()
  File "/Library/Frameworks/Python.framework/Versions/3.7/lib/python3.7/site-packages/pymysql/connections.py", line 684, in _read_packet
    packet.check_error()
  File "/Library/Frameworks/Python.framework/Versions/3.7/lib/python3.7/site-packages/pymysql/protocol.py", line 220, in check_error
    err.raise_mysql_exception(self._data)
  File "/Library/Frameworks/Python.framework/Versions/3.7/lib/python3.7/site-packages/pymysql/err.py", line 109, in raise_mysql_exception
    raise errorclass(errno, errval)
pymysql.err.InternalError: (1054, "Unknown column 'name' in 'field list'")

During handling of the above exception, another exception occurred:

Traceback (most recent call last):
  File "/Library/Frameworks/Python.framework/Versions/3.7/lib/python3.7/site-packages/twisted/internet/defer.py", line 654, in _runCallbacks
    current.result = callback(current.result, *args, **kw)
  File "/Library/Frameworks/Python.framework/Versions/3.7/lib/python3.7/site-packages/scrapy/utils/defer.py", line 154, in f
    return deferred_from_coro(coro_f(*coro_args, **coro_kwargs))
  File "/Users/zhangzhuoyu 1/homework/Python001-class01/week02/作业一/movies/movies/pipelines.py", line 55, in process_item
    self.logger.error(e)
AttributeError: 'MoviesPipeline' object has no attribute 'logger'
2020-07-06 22:36:46 [scrapy.core.scraper] ERROR: Error processing {'movie_name': '冰雪奇缘2', 'movie_time': '2019-11-22', 'movie_type': '喜剧／动画／冒险'}
Traceback (most recent call last):
  File "/Users/zhangzhuoyu 1/homework/Python001-class01/week02/作业一/movies/movies/pipelines.py", line 50, in process_item
    self.cursor.execute(sql)
  File "/Library/Frameworks/Python.framework/Versions/3.7/lib/python3.7/site-packages/pymysql/cursors.py", line 170, in execute
    result = self._query(query)
  File "/Library/Frameworks/Python.framework/Versions/3.7/lib/python3.7/site-packages/pymysql/cursors.py", line 328, in _query
    conn.query(q)
  File "/Library/Frameworks/Python.framework/Versions/3.7/lib/python3.7/site-packages/pymysql/connections.py", line 517, in query
    self._affected_rows = self._read_query_result(unbuffered=unbuffered)
  File "/Library/Frameworks/Python.framework/Versions/3.7/lib/python3.7/site-packages/pymysql/connections.py", line 732, in _read_query_result
    result.read()
  File "/Library/Frameworks/Python.framework/Versions/3.7/lib/python3.7/site-packages/pymysql/connections.py", line 1075, in read
    first_packet = self.connection._read_packet()
  File "/Library/Frameworks/Python.framework/Versions/3.7/lib/python3.7/site-packages/pymysql/connections.py", line 684, in _read_packet
    packet.check_error()
  File "/Library/Frameworks/Python.framework/Versions/3.7/lib/python3.7/site-packages/pymysql/protocol.py", line 220, in check_error
    err.raise_mysql_exception(self._data)
  File "/Library/Frameworks/Python.framework/Versions/3.7/lib/python3.7/site-packages/pymysql/err.py", line 109, in raise_mysql_exception
    raise errorclass(errno, errval)
pymysql.err.InternalError: (1054, "Unknown column 'name' in 'field list'")

During handling of the above exception, another exception occurred:

Traceback (most recent call last):
  File "/Library/Frameworks/Python.framework/Versions/3.7/lib/python3.7/site-packages/twisted/internet/defer.py", line 654, in _runCallbacks
    current.result = callback(current.result, *args, **kw)
  File "/Library/Frameworks/Python.framework/Versions/3.7/lib/python3.7/site-packages/scrapy/utils/defer.py", line 154, in f
    return deferred_from_coro(coro_f(*coro_args, **coro_kwargs))
  File "/Users/zhangzhuoyu 1/homework/Python001-class01/week02/作业一/movies/movies/pipelines.py", line 55, in process_item
    self.logger.error(e)
AttributeError: 'MoviesPipeline' object has no attribute 'logger'
2020-07-06 22:36:46 [scrapy.core.scraper] ERROR: Error processing {'movie_name': '我和我的祖国', 'movie_time': '2019-09-30', 'movie_type': '剧情'}
Traceback (most recent call last):
  File "/Users/zhangzhuoyu 1/homework/Python001-class01/week02/作业一/movies/movies/pipelines.py", line 50, in process_item
    self.cursor.execute(sql)
  File "/Library/Frameworks/Python.framework/Versions/3.7/lib/python3.7/site-packages/pymysql/cursors.py", line 170, in execute
    result = self._query(query)
  File "/Library/Frameworks/Python.framework/Versions/3.7/lib/python3.7/site-packages/pymysql/cursors.py", line 328, in _query
    conn.query(q)
  File "/Library/Frameworks/Python.framework/Versions/3.7/lib/python3.7/site-packages/pymysql/connections.py", line 517, in query
    self._affected_rows = self._read_query_result(unbuffered=unbuffered)
  File "/Library/Frameworks/Python.framework/Versions/3.7/lib/python3.7/site-packages/pymysql/connections.py", line 732, in _read_query_result
    result.read()
  File "/Library/Frameworks/Python.framework/Versions/3.7/lib/python3.7/site-packages/pymysql/connections.py", line 1075, in read
    first_packet = self.connection._read_packet()
  File "/Library/Frameworks/Python.framework/Versions/3.7/lib/python3.7/site-packages/pymysql/connections.py", line 684, in _read_packet
    packet.check_error()
  File "/Library/Frameworks/Python.framework/Versions/3.7/lib/python3.7/site-packages/pymysql/protocol.py", line 220, in check_error
    err.raise_mysql_exception(self._data)
  File "/Library/Frameworks/Python.framework/Versions/3.7/lib/python3.7/site-packages/pymysql/err.py", line 109, in raise_mysql_exception
    raise errorclass(errno, errval)
pymysql.err.InternalError: (1054, "Unknown column 'name' in 'field list'")

During handling of the above exception, another exception occurred:

Traceback (most recent call last):
  File "/Library/Frameworks/Python.framework/Versions/3.7/lib/python3.7/site-packages/twisted/internet/defer.py", line 654, in _runCallbacks
    current.result = callback(current.result, *args, **kw)
  File "/Library/Frameworks/Python.framework/Versions/3.7/lib/python3.7/site-packages/scrapy/utils/defer.py", line 154, in f
    return deferred_from_coro(coro_f(*coro_args, **coro_kwargs))
  File "/Users/zhangzhuoyu 1/homework/Python001-class01/week02/作业一/movies/movies/pipelines.py", line 55, in process_item
    self.logger.error(e)
AttributeError: 'MoviesPipeline' object has no attribute 'logger'
2020-07-06 22:36:46 [scrapy.core.scraper] ERROR: Error processing {'movie_name': '吹哨人', 'movie_time': '2019-12-06', 'movie_type': '剧情／犯罪／悬疑'}
Traceback (most recent call last):
  File "/Users/zhangzhuoyu 1/homework/Python001-class01/week02/作业一/movies/movies/pipelines.py", line 50, in process_item
    self.cursor.execute(sql)
  File "/Library/Frameworks/Python.framework/Versions/3.7/lib/python3.7/site-packages/pymysql/cursors.py", line 170, in execute
    result = self._query(query)
  File "/Library/Frameworks/Python.framework/Versions/3.7/lib/python3.7/site-packages/pymysql/cursors.py", line 328, in _query
    conn.query(q)
  File "/Library/Frameworks/Python.framework/Versions/3.7/lib/python3.7/site-packages/pymysql/connections.py", line 517, in query
    self._affected_rows = self._read_query_result(unbuffered=unbuffered)
  File "/Library/Frameworks/Python.framework/Versions/3.7/lib/python3.7/site-packages/pymysql/connections.py", line 732, in _read_query_result
    result.read()
  File "/Library/Frameworks/Python.framework/Versions/3.7/lib/python3.7/site-packages/pymysql/connections.py", line 1075, in read
    first_packet = self.connection._read_packet()
  File "/Library/Frameworks/Python.framework/Versions/3.7/lib/python3.7/site-packages/pymysql/connections.py", line 684, in _read_packet
    packet.check_error()
  File "/Library/Frameworks/Python.framework/Versions/3.7/lib/python3.7/site-packages/pymysql/protocol.py", line 220, in check_error
    err.raise_mysql_exception(self._data)
  File "/Library/Frameworks/Python.framework/Versions/3.7/lib/python3.7/site-packages/pymysql/err.py", line 109, in raise_mysql_exception
    raise errorclass(errno, errval)
pymysql.err.InternalError: (1054, "Unknown column 'name' in 'field list'")

During handling of the above exception, another exception occurred:

Traceback (most recent call last):
  File "/Library/Frameworks/Python.framework/Versions/3.7/lib/python3.7/site-packages/twisted/internet/defer.py", line 654, in _runCallbacks
    current.result = callback(current.result, *args, **kw)
  File "/Library/Frameworks/Python.framework/Versions/3.7/lib/python3.7/site-packages/scrapy/utils/defer.py", line 154, in f
    return deferred_from_coro(coro_f(*coro_args, **coro_kwargs))
  File "/Users/zhangzhuoyu 1/homework/Python001-class01/week02/作业一/movies/movies/pipelines.py", line 55, in process_item
    self.logger.error(e)
AttributeError: 'MoviesPipeline' object has no attribute 'logger'
2020-07-06 22:36:46 [scrapy.core.scraper] ERROR: Error processing {'movie_name': '诛仙1', 'movie_time': '2019-09-13', 'movie_type': '古装／爱情／奇幻'}
Traceback (most recent call last):
  File "/Users/zhangzhuoyu 1/homework/Python001-class01/week02/作业一/movies/movies/pipelines.py", line 50, in process_item
    self.cursor.execute(sql)
  File "/Library/Frameworks/Python.framework/Versions/3.7/lib/python3.7/site-packages/pymysql/cursors.py", line 170, in execute
    result = self._query(query)
  File "/Library/Frameworks/Python.framework/Versions/3.7/lib/python3.7/site-packages/pymysql/cursors.py", line 328, in _query
    conn.query(q)
  File "/Library/Frameworks/Python.framework/Versions/3.7/lib/python3.7/site-packages/pymysql/connections.py", line 517, in query
    self._affected_rows = self._read_query_result(unbuffered=unbuffered)
  File "/Library/Frameworks/Python.framework/Versions/3.7/lib/python3.7/site-packages/pymysql/connections.py", line 732, in _read_query_result
    result.read()
  File "/Library/Frameworks/Python.framework/Versions/3.7/lib/python3.7/site-packages/pymysql/connections.py", line 1075, in read
    first_packet = self.connection._read_packet()
  File "/Library/Frameworks/Python.framework/Versions/3.7/lib/python3.7/site-packages/pymysql/connections.py", line 684, in _read_packet
    packet.check_error()
  File "/Library/Frameworks/Python.framework/Versions/3.7/lib/python3.7/site-packages/pymysql/protocol.py", line 220, in check_error
    err.raise_mysql_exception(self._data)
  File "/Library/Frameworks/Python.framework/Versions/3.7/lib/python3.7/site-packages/pymysql/err.py", line 109, in raise_mysql_exception
    raise errorclass(errno, errval)
pymysql.err.InternalError: (1054, "Unknown column 'name' in 'field list'")

During handling of the above exception, another exception occurred:

Traceback (most recent call last):
  File "/Library/Frameworks/Python.framework/Versions/3.7/lib/python3.7/site-packages/twisted/internet/defer.py", line 654, in _runCallbacks
    current.result = callback(current.result, *args, **kw)
  File "/Library/Frameworks/Python.framework/Versions/3.7/lib/python3.7/site-packages/scrapy/utils/defer.py", line 154, in f
    return deferred_from_coro(coro_f(*coro_args, **coro_kwargs))
  File "/Users/zhangzhuoyu 1/homework/Python001-class01/week02/作业一/movies/movies/pipelines.py", line 55, in process_item
    self.logger.error(e)
AttributeError: 'MoviesPipeline' object has no attribute 'logger'
2020-07-06 22:36:46 [scrapy.core.scraper] ERROR: Error processing {'movie_name': '中国机长', 'movie_time': '2019-09-30', 'movie_type': '剧情／传记'}
Traceback (most recent call last):
  File "/Users/zhangzhuoyu 1/homework/Python001-class01/week02/作业一/movies/movies/pipelines.py", line 50, in process_item
    self.cursor.execute(sql)
  File "/Library/Frameworks/Python.framework/Versions/3.7/lib/python3.7/site-packages/pymysql/cursors.py", line 170, in execute
    result = self._query(query)
  File "/Library/Frameworks/Python.framework/Versions/3.7/lib/python3.7/site-packages/pymysql/cursors.py", line 328, in _query
    conn.query(q)
  File "/Library/Frameworks/Python.framework/Versions/3.7/lib/python3.7/site-packages/pymysql/connections.py", line 517, in query
    self._affected_rows = self._read_query_result(unbuffered=unbuffered)
  File "/Library/Frameworks/Python.framework/Versions/3.7/lib/python3.7/site-packages/pymysql/connections.py", line 732, in _read_query_result
    result.read()
  File "/Library/Frameworks/Python.framework/Versions/3.7/lib/python3.7/site-packages/pymysql/connections.py", line 1075, in read
    first_packet = self.connection._read_packet()
  File "/Library/Frameworks/Python.framework/Versions/3.7/lib/python3.7/site-packages/pymysql/connections.py", line 684, in _read_packet
    packet.check_error()
  File "/Library/Frameworks/Python.framework/Versions/3.7/lib/python3.7/site-packages/pymysql/protocol.py", line 220, in check_error
    err.raise_mysql_exception(self._data)
  File "/Library/Frameworks/Python.framework/Versions/3.7/lib/python3.7/site-packages/pymysql/err.py", line 109, in raise_mysql_exception
    raise errorclass(errno, errval)
pymysql.err.InternalError: (1054, "Unknown column 'name' in 'field list'")

During handling of the above exception, another exception occurred:

Traceback (most recent call last):
  File "/Library/Frameworks/Python.framework/Versions/3.7/lib/python3.7/site-packages/twisted/internet/defer.py", line 654, in _runCallbacks
    current.result = callback(current.result, *args, **kw)
  File "/Library/Frameworks/Python.framework/Versions/3.7/lib/python3.7/site-packages/scrapy/utils/defer.py", line 154, in f
    return deferred_from_coro(coro_f(*coro_args, **coro_kwargs))
  File "/Users/zhangzhuoyu 1/homework/Python001-class01/week02/作业一/movies/movies/pipelines.py", line 55, in process_item
    self.logger.error(e)
AttributeError: 'MoviesPipeline' object has no attribute 'logger'
2020-07-06 22:36:46 [scrapy.core.scraper] ERROR: Error processing {'movie_name': '宠爱', 'movie_time': '2019-12-31', 'movie_type': '喜剧／爱情／剧情'}
Traceback (most recent call last):
  File "/Users/zhangzhuoyu 1/homework/Python001-class01/week02/作业一/movies/movies/pipelines.py", line 50, in process_item
    self.cursor.execute(sql)
  File "/Library/Frameworks/Python.framework/Versions/3.7/lib/python3.7/site-packages/pymysql/cursors.py", line 170, in execute
    result = self._query(query)
  File "/Library/Frameworks/Python.framework/Versions/3.7/lib/python3.7/site-packages/pymysql/cursors.py", line 328, in _query
    conn.query(q)
  File "/Library/Frameworks/Python.framework/Versions/3.7/lib/python3.7/site-packages/pymysql/connections.py", line 517, in query
    self._affected_rows = self._read_query_result(unbuffered=unbuffered)
  File "/Library/Frameworks/Python.framework/Versions/3.7/lib/python3.7/site-packages/pymysql/connections.py", line 732, in _read_query_result
    result.read()
  File "/Library/Frameworks/Python.framework/Versions/3.7/lib/python3.7/site-packages/pymysql/connections.py", line 1075, in read
    first_packet = self.connection._read_packet()
  File "/Library/Frameworks/Python.framework/Versions/3.7/lib/python3.7/site-packages/pymysql/connections.py", line 684, in _read_packet
    packet.check_error()
  File "/Library/Frameworks/Python.framework/Versions/3.7/lib/python3.7/site-packages/pymysql/protocol.py", line 220, in check_error
    err.raise_mysql_exception(self._data)
  File "/Library/Frameworks/Python.framework/Versions/3.7/lib/python3.7/site-packages/pymysql/err.py", line 109, in raise_mysql_exception
    raise errorclass(errno, errval)
pymysql.err.InternalError: (1054, "Unknown column 'name' in 'field list'")

During handling of the above exception, another exception occurred:

Traceback (most recent call last):
  File "/Library/Frameworks/Python.framework/Versions/3.7/lib/python3.7/site-packages/twisted/internet/defer.py", line 654, in _runCallbacks
    current.result = callback(current.result, *args, **kw)
  File "/Library/Frameworks/Python.framework/Versions/3.7/lib/python3.7/site-packages/scrapy/utils/defer.py", line 154, in f
    return deferred_from_coro(coro_f(*coro_args, **coro_kwargs))
  File "/Users/zhangzhuoyu 1/homework/Python001-class01/week02/作业一/movies/movies/pipelines.py", line 55, in process_item
    self.logger.error(e)
AttributeError: 'MoviesPipeline' object has no attribute 'logger'
2020-07-06 22:36:46 [scrapy.core.scraper] ERROR: Error processing {'movie_name': '疯狂的外星人', 'movie_time': '2019-02-05', 'movie_type': '剧情／喜剧／科幻'}
Traceback (most recent call last):
  File "/Users/zhangzhuoyu 1/homework/Python001-class01/week02/作业一/movies/movies/pipelines.py", line 50, in process_item
    self.cursor.execute(sql)
  File "/Library/Frameworks/Python.framework/Versions/3.7/lib/python3.7/site-packages/pymysql/cursors.py", line 170, in execute
    result = self._query(query)
  File "/Library/Frameworks/Python.framework/Versions/3.7/lib/python3.7/site-packages/pymysql/cursors.py", line 328, in _query
    conn.query(q)
  File "/Library/Frameworks/Python.framework/Versions/3.7/lib/python3.7/site-packages/pymysql/connections.py", line 517, in query
    self._affected_rows = self._read_query_result(unbuffered=unbuffered)
  File "/Library/Frameworks/Python.framework/Versions/3.7/lib/python3.7/site-packages/pymysql/connections.py", line 732, in _read_query_result
    result.read()
  File "/Library/Frameworks/Python.framework/Versions/3.7/lib/python3.7/site-packages/pymysql/connections.py", line 1075, in read
    first_packet = self.connection._read_packet()
  File "/Library/Frameworks/Python.framework/Versions/3.7/lib/python3.7/site-packages/pymysql/connections.py", line 684, in _read_packet
    packet.check_error()
  File "/Library/Frameworks/Python.framework/Versions/3.7/lib/python3.7/site-packages/pymysql/protocol.py", line 220, in check_error
    err.raise_mysql_exception(self._data)
  File "/Library/Frameworks/Python.framework/Versions/3.7/lib/python3.7/site-packages/pymysql/err.py", line 109, in raise_mysql_exception
    raise errorclass(errno, errval)
pymysql.err.InternalError: (1054, "Unknown column 'name' in 'field list'")

During handling of the above exception, another exception occurred:

Traceback (most recent call last):
  File "/Library/Frameworks/Python.framework/Versions/3.7/lib/python3.7/site-packages/twisted/internet/defer.py", line 654, in _runCallbacks
    current.result = callback(current.result, *args, **kw)
  File "/Library/Frameworks/Python.framework/Versions/3.7/lib/python3.7/site-packages/scrapy/utils/defer.py", line 154, in f
    return deferred_from_coro(coro_f(*coro_args, **coro_kwargs))
  File "/Users/zhangzhuoyu 1/homework/Python001-class01/week02/作业一/movies/movies/pipelines.py", line 55, in process_item
    self.logger.error(e)
AttributeError: 'MoviesPipeline' object has no attribute 'logger'
2020-07-06 22:36:46 [scrapy.core.scraper] ERROR: Error processing {'movie_name': '流浪地球', 'movie_time': '2019-02-05', 'movie_type': '剧情／冒险／科幻'}
Traceback (most recent call last):
  File "/Users/zhangzhuoyu 1/homework/Python001-class01/week02/作业一/movies/movies/pipelines.py", line 50, in process_item
    self.cursor.execute(sql)
  File "/Library/Frameworks/Python.framework/Versions/3.7/lib/python3.7/site-packages/pymysql/cursors.py", line 170, in execute
    result = self._query(query)
  File "/Library/Frameworks/Python.framework/Versions/3.7/lib/python3.7/site-packages/pymysql/cursors.py", line 328, in _query
    conn.query(q)
  File "/Library/Frameworks/Python.framework/Versions/3.7/lib/python3.7/site-packages/pymysql/connections.py", line 517, in query
    self._affected_rows = self._read_query_result(unbuffered=unbuffered)
  File "/Library/Frameworks/Python.framework/Versions/3.7/lib/python3.7/site-packages/pymysql/connections.py", line 732, in _read_query_result
    result.read()
  File "/Library/Frameworks/Python.framework/Versions/3.7/lib/python3.7/site-packages/pymysql/connections.py", line 1075, in read
    first_packet = self.connection._read_packet()
  File "/Library/Frameworks/Python.framework/Versions/3.7/lib/python3.7/site-packages/pymysql/connections.py", line 684, in _read_packet
    packet.check_error()
  File "/Library/Frameworks/Python.framework/Versions/3.7/lib/python3.7/site-packages/pymysql/protocol.py", line 220, in check_error
    err.raise_mysql_exception(self._data)
  File "/Library/Frameworks/Python.framework/Versions/3.7/lib/python3.7/site-packages/pymysql/err.py", line 109, in raise_mysql_exception
    raise errorclass(errno, errval)
pymysql.err.InternalError: (1054, "Unknown column 'name' in 'field list'")

During handling of the above exception, another exception occurred:

Traceback (most recent call last):
  File "/Library/Frameworks/Python.framework/Versions/3.7/lib/python3.7/site-packages/twisted/internet/defer.py", line 654, in _runCallbacks
    current.result = callback(current.result, *args, **kw)
  File "/Library/Frameworks/Python.framework/Versions/3.7/lib/python3.7/site-packages/scrapy/utils/defer.py", line 154, in f
    return deferred_from_coro(coro_f(*coro_args, **coro_kwargs))
  File "/Users/zhangzhuoyu 1/homework/Python001-class01/week02/作业一/movies/movies/pipelines.py", line 55, in process_item
    self.logger.error(e)
AttributeError: 'MoviesPipeline' object has no attribute 'logger'
2020-07-06 22:36:46 [scrapy.core.scraper] ERROR: Error processing {'movie_name': '两只老虎', 'movie_time': '2019-11-29', 'movie_type': '剧情／喜剧'}
Traceback (most recent call last):
  File "/Users/zhangzhuoyu 1/homework/Python001-class01/week02/作业一/movies/movies/pipelines.py", line 50, in process_item
    self.cursor.execute(sql)
  File "/Library/Frameworks/Python.framework/Versions/3.7/lib/python3.7/site-packages/pymysql/cursors.py", line 170, in execute
    result = self._query(query)
  File "/Library/Frameworks/Python.framework/Versions/3.7/lib/python3.7/site-packages/pymysql/cursors.py", line 328, in _query
    conn.query(q)
  File "/Library/Frameworks/Python.framework/Versions/3.7/lib/python3.7/site-packages/pymysql/connections.py", line 517, in query
    self._affected_rows = self._read_query_result(unbuffered=unbuffered)
  File "/Library/Frameworks/Python.framework/Versions/3.7/lib/python3.7/site-packages/pymysql/connections.py", line 732, in _read_query_result
    result.read()
  File "/Library/Frameworks/Python.framework/Versions/3.7/lib/python3.7/site-packages/pymysql/connections.py", line 1075, in read
    first_packet = self.connection._read_packet()
  File "/Library/Frameworks/Python.framework/Versions/3.7/lib/python3.7/site-packages/pymysql/connections.py", line 684, in _read_packet
    packet.check_error()
  File "/Library/Frameworks/Python.framework/Versions/3.7/lib/python3.7/site-packages/pymysql/protocol.py", line 220, in check_error
    err.raise_mysql_exception(self._data)
  File "/Library/Frameworks/Python.framework/Versions/3.7/lib/python3.7/site-packages/pymysql/err.py", line 109, in raise_mysql_exception
    raise errorclass(errno, errval)
pymysql.err.InternalError: (1054, "Unknown column 'name' in 'field list'")

During handling of the above exception, another exception occurred:

Traceback (most recent call last):
  File "/Library/Frameworks/Python.framework/Versions/3.7/lib/python3.7/site-packages/twisted/internet/defer.py", line 654, in _runCallbacks
    current.result = callback(current.result, *args, **kw)
  File "/Library/Frameworks/Python.framework/Versions/3.7/lib/python3.7/site-packages/scrapy/utils/defer.py", line 154, in f
    return deferred_from_coro(coro_f(*coro_args, **coro_kwargs))
  File "/Users/zhangzhuoyu 1/homework/Python001-class01/week02/作业一/movies/movies/pipelines.py", line 55, in process_item
    self.logger.error(e)
AttributeError: 'MoviesPipeline' object has no attribute 'logger'
2020-07-06 22:36:46 [scrapy.core.scraper] ERROR: Error processing {'movie_name': '釜山行', 'movie_time': '2016-05-13', 'movie_type': '动作／惊悚／灾难'}
Traceback (most recent call last):
  File "/Users/zhangzhuoyu 1/homework/Python001-class01/week02/作业一/movies/movies/pipelines.py", line 50, in process_item
    self.cursor.execute(sql)
  File "/Library/Frameworks/Python.framework/Versions/3.7/lib/python3.7/site-packages/pymysql/cursors.py", line 170, in execute
    result = self._query(query)
  File "/Library/Frameworks/Python.framework/Versions/3.7/lib/python3.7/site-packages/pymysql/cursors.py", line 328, in _query
    conn.query(q)
  File "/Library/Frameworks/Python.framework/Versions/3.7/lib/python3.7/site-packages/pymysql/connections.py", line 517, in query
    self._affected_rows = self._read_query_result(unbuffered=unbuffered)
  File "/Library/Frameworks/Python.framework/Versions/3.7/lib/python3.7/site-packages/pymysql/connections.py", line 732, in _read_query_result
    result.read()
  File "/Library/Frameworks/Python.framework/Versions/3.7/lib/python3.7/site-packages/pymysql/connections.py", line 1075, in read
    first_packet = self.connection._read_packet()
  File "/Library/Frameworks/Python.framework/Versions/3.7/lib/python3.7/site-packages/pymysql/connections.py", line 684, in _read_packet
    packet.check_error()
  File "/Library/Frameworks/Python.framework/Versions/3.7/lib/python3.7/site-packages/pymysql/protocol.py", line 220, in check_error
    err.raise_mysql_exception(self._data)
  File "/Library/Frameworks/Python.framework/Versions/3.7/lib/python3.7/site-packages/pymysql/err.py", line 109, in raise_mysql_exception
    raise errorclass(errno, errval)
pymysql.err.InternalError: (1054, "Unknown column 'name' in 'field list'")

During handling of the above exception, another exception occurred:

Traceback (most recent call last):
  File "/Library/Frameworks/Python.framework/Versions/3.7/lib/python3.7/site-packages/twisted/internet/defer.py", line 654, in _runCallbacks
    current.result = callback(current.result, *args, **kw)
  File "/Library/Frameworks/Python.framework/Versions/3.7/lib/python3.7/site-packages/scrapy/utils/defer.py", line 154, in f
    return deferred_from_coro(coro_f(*coro_args, **coro_kwargs))
  File "/Users/zhangzhuoyu 1/homework/Python001-class01/week02/作业一/movies/movies/pipelines.py", line 55, in process_item
    self.logger.error(e)
AttributeError: 'MoviesPipeline' object has no attribute 'logger'
2020-07-06 22:36:46 [scrapy.core.scraper] ERROR: Error processing {'movie_name': '数码宝贝大冒险：最后的进化·羁绊',
 'movie_time': '2020-02-21',
 'movie_type': '动画／冒险'}
Traceback (most recent call last):
  File "/Users/zhangzhuoyu 1/homework/Python001-class01/week02/作业一/movies/movies/pipelines.py", line 50, in process_item
    self.cursor.execute(sql)
  File "/Library/Frameworks/Python.framework/Versions/3.7/lib/python3.7/site-packages/pymysql/cursors.py", line 170, in execute
    result = self._query(query)
  File "/Library/Frameworks/Python.framework/Versions/3.7/lib/python3.7/site-packages/pymysql/cursors.py", line 328, in _query
    conn.query(q)
  File "/Library/Frameworks/Python.framework/Versions/3.7/lib/python3.7/site-packages/pymysql/connections.py", line 517, in query
    self._affected_rows = self._read_query_result(unbuffered=unbuffered)
  File "/Library/Frameworks/Python.framework/Versions/3.7/lib/python3.7/site-packages/pymysql/connections.py", line 732, in _read_query_result
    result.read()
  File "/Library/Frameworks/Python.framework/Versions/3.7/lib/python3.7/site-packages/pymysql/connections.py", line 1075, in read
    first_packet = self.connection._read_packet()
  File "/Library/Frameworks/Python.framework/Versions/3.7/lib/python3.7/site-packages/pymysql/connections.py", line 684, in _read_packet
    packet.check_error()
  File "/Library/Frameworks/Python.framework/Versions/3.7/lib/python3.7/site-packages/pymysql/protocol.py", line 220, in check_error
    err.raise_mysql_exception(self._data)
  File "/Library/Frameworks/Python.framework/Versions/3.7/lib/python3.7/site-packages/pymysql/err.py", line 109, in raise_mysql_exception
    raise errorclass(errno, errval)
pymysql.err.InternalError: (1054, "Unknown column 'name' in 'field list'")

During handling of the above exception, another exception occurred:

Traceback (most recent call last):
  File "/Library/Frameworks/Python.framework/Versions/3.7/lib/python3.7/site-packages/twisted/internet/defer.py", line 654, in _runCallbacks
    current.result = callback(current.result, *args, **kw)
  File "/Library/Frameworks/Python.framework/Versions/3.7/lib/python3.7/site-packages/scrapy/utils/defer.py", line 154, in f
    return deferred_from_coro(coro_f(*coro_args, **coro_kwargs))
  File "/Users/zhangzhuoyu 1/homework/Python001-class01/week02/作业一/movies/movies/pipelines.py", line 55, in process_item
    self.logger.error(e)
AttributeError: 'MoviesPipeline' object has no attribute 'logger'
2020-07-06 22:36:46 [scrapy.core.scraper] ERROR: Error processing {'movie_name': '因爱而伟大', 'movie_time': '', 'movie_type': '剧情／家庭'}
Traceback (most recent call last):
  File "/Users/zhangzhuoyu 1/homework/Python001-class01/week02/作业一/movies/movies/pipelines.py", line 50, in process_item
    self.cursor.execute(sql)
  File "/Library/Frameworks/Python.framework/Versions/3.7/lib/python3.7/site-packages/pymysql/cursors.py", line 170, in execute
    result = self._query(query)
  File "/Library/Frameworks/Python.framework/Versions/3.7/lib/python3.7/site-packages/pymysql/cursors.py", line 328, in _query
    conn.query(q)
  File "/Library/Frameworks/Python.framework/Versions/3.7/lib/python3.7/site-packages/pymysql/connections.py", line 517, in query
    self._affected_rows = self._read_query_result(unbuffered=unbuffered)
  File "/Library/Frameworks/Python.framework/Versions/3.7/lib/python3.7/site-packages/pymysql/connections.py", line 732, in _read_query_result
    result.read()
  File "/Library/Frameworks/Python.framework/Versions/3.7/lib/python3.7/site-packages/pymysql/connections.py", line 1075, in read
    first_packet = self.connection._read_packet()
  File "/Library/Frameworks/Python.framework/Versions/3.7/lib/python3.7/site-packages/pymysql/connections.py", line 684, in _read_packet
    packet.check_error()
  File "/Library/Frameworks/Python.framework/Versions/3.7/lib/python3.7/site-packages/pymysql/protocol.py", line 220, in check_error
    err.raise_mysql_exception(self._data)
  File "/Library/Frameworks/Python.framework/Versions/3.7/lib/python3.7/site-packages/pymysql/err.py", line 109, in raise_mysql_exception
    raise errorclass(errno, errval)
pymysql.err.InternalError: (1054, "Unknown column 'name' in 'field list'")

During handling of the above exception, another exception occurred:

Traceback (most recent call last):
  File "/Library/Frameworks/Python.framework/Versions/3.7/lib/python3.7/site-packages/twisted/internet/defer.py", line 654, in _runCallbacks
    current.result = callback(current.result, *args, **kw)
  File "/Library/Frameworks/Python.framework/Versions/3.7/lib/python3.7/site-packages/scrapy/utils/defer.py", line 154, in f
    return deferred_from_coro(coro_f(*coro_args, **coro_kwargs))
  File "/Users/zhangzhuoyu 1/homework/Python001-class01/week02/作业一/movies/movies/pipelines.py", line 55, in process_item
    self.logger.error(e)
AttributeError: 'MoviesPipeline' object has no attribute 'logger'
2020-07-06 22:36:46 [scrapy.core.scraper] ERROR: Error processing {'movie_name': '最美逆行', 'movie_time': '2020-06-28', 'movie_type': '剧情'}
Traceback (most recent call last):
  File "/Users/zhangzhuoyu 1/homework/Python001-class01/week02/作业一/movies/movies/pipelines.py", line 50, in process_item
    self.cursor.execute(sql)
  File "/Library/Frameworks/Python.framework/Versions/3.7/lib/python3.7/site-packages/pymysql/cursors.py", line 170, in execute
    result = self._query(query)
  File "/Library/Frameworks/Python.framework/Versions/3.7/lib/python3.7/site-packages/pymysql/cursors.py", line 328, in _query
    conn.query(q)
  File "/Library/Frameworks/Python.framework/Versions/3.7/lib/python3.7/site-packages/pymysql/connections.py", line 517, in query
    self._affected_rows = self._read_query_result(unbuffered=unbuffered)
  File "/Library/Frameworks/Python.framework/Versions/3.7/lib/python3.7/site-packages/pymysql/connections.py", line 732, in _read_query_result
    result.read()
  File "/Library/Frameworks/Python.framework/Versions/3.7/lib/python3.7/site-packages/pymysql/connections.py", line 1075, in read
    first_packet = self.connection._read_packet()
  File "/Library/Frameworks/Python.framework/Versions/3.7/lib/python3.7/site-packages/pymysql/connections.py", line 684, in _read_packet
    packet.check_error()
  File "/Library/Frameworks/Python.framework/Versions/3.7/lib/python3.7/site-packages/pymysql/protocol.py", line 220, in check_error
    err.raise_mysql_exception(self._data)
  File "/Library/Frameworks/Python.framework/Versions/3.7/lib/python3.7/site-packages/pymysql/err.py", line 109, in raise_mysql_exception
    raise errorclass(errno, errval)
pymysql.err.InternalError: (1054, "Unknown column 'name' in 'field list'")

During handling of the above exception, another exception occurred:

Traceback (most recent call last):
  File "/Library/Frameworks/Python.framework/Versions/3.7/lib/python3.7/site-packages/twisted/internet/defer.py", line 654, in _runCallbacks
    current.result = callback(current.result, *args, **kw)
  File "/Library/Frameworks/Python.framework/Versions/3.7/lib/python3.7/site-packages/scrapy/utils/defer.py", line 154, in f
    return deferred_from_coro(coro_f(*coro_args, **coro_kwargs))
  File "/Users/zhangzhuoyu 1/homework/Python001-class01/week02/作业一/movies/movies/pipelines.py", line 55, in process_item
    self.logger.error(e)
AttributeError: 'MoviesPipeline' object has no attribute 'logger'
2020-07-06 22:36:46 [scrapy.core.scraper] ERROR: Error processing {'movie_name': '攀登者', 'movie_time': '2019-09-30', 'movie_type': '剧情／冒险'}
Traceback (most recent call last):
  File "/Users/zhangzhuoyu 1/homework/Python001-class01/week02/作业一/movies/movies/pipelines.py", line 50, in process_item
    self.cursor.execute(sql)
  File "/Library/Frameworks/Python.framework/Versions/3.7/lib/python3.7/site-packages/pymysql/cursors.py", line 170, in execute
    result = self._query(query)
  File "/Library/Frameworks/Python.framework/Versions/3.7/lib/python3.7/site-packages/pymysql/cursors.py", line 328, in _query
    conn.query(q)
  File "/Library/Frameworks/Python.framework/Versions/3.7/lib/python3.7/site-packages/pymysql/connections.py", line 517, in query
    self._affected_rows = self._read_query_result(unbuffered=unbuffered)
  File "/Library/Frameworks/Python.framework/Versions/3.7/lib/python3.7/site-packages/pymysql/connections.py", line 732, in _read_query_result
    result.read()
  File "/Library/Frameworks/Python.framework/Versions/3.7/lib/python3.7/site-packages/pymysql/connections.py", line 1075, in read
    first_packet = self.connection._read_packet()
  File "/Library/Frameworks/Python.framework/Versions/3.7/lib/python3.7/site-packages/pymysql/connections.py", line 684, in _read_packet
    packet.check_error()
  File "/Library/Frameworks/Python.framework/Versions/3.7/lib/python3.7/site-packages/pymysql/protocol.py", line 220, in check_error
    err.raise_mysql_exception(self._data)
  File "/Library/Frameworks/Python.framework/Versions/3.7/lib/python3.7/site-packages/pymysql/err.py", line 109, in raise_mysql_exception
    raise errorclass(errno, errval)
pymysql.err.InternalError: (1054, "Unknown column 'name' in 'field list'")

During handling of the above exception, another exception occurred:

Traceback (most recent call last):
  File "/Library/Frameworks/Python.framework/Versions/3.7/lib/python3.7/site-packages/twisted/internet/defer.py", line 654, in _runCallbacks
    current.result = callback(current.result, *args, **kw)
  File "/Library/Frameworks/Python.framework/Versions/3.7/lib/python3.7/site-packages/scrapy/utils/defer.py", line 154, in f
    return deferred_from_coro(coro_f(*coro_args, **coro_kwargs))
  File "/Users/zhangzhuoyu 1/homework/Python001-class01/week02/作业一/movies/movies/pipelines.py", line 55, in process_item
    self.logger.error(e)
AttributeError: 'MoviesPipeline' object has no attribute 'logger'
2020-07-06 22:36:46 [scrapy.core.scraper] ERROR: Error processing {'movie_name': '银河补习班', 'movie_time': '2019-07-18', 'movie_type': '剧情／家庭'}
Traceback (most recent call last):
  File "/Users/zhangzhuoyu 1/homework/Python001-class01/week02/作业一/movies/movies/pipelines.py", line 50, in process_item
    self.cursor.execute(sql)
  File "/Library/Frameworks/Python.framework/Versions/3.7/lib/python3.7/site-packages/pymysql/cursors.py", line 170, in execute
    result = self._query(query)
  File "/Library/Frameworks/Python.framework/Versions/3.7/lib/python3.7/site-packages/pymysql/cursors.py", line 328, in _query
    conn.query(q)
  File "/Library/Frameworks/Python.framework/Versions/3.7/lib/python3.7/site-packages/pymysql/connections.py", line 517, in query
    self._affected_rows = self._read_query_result(unbuffered=unbuffered)
  File "/Library/Frameworks/Python.framework/Versions/3.7/lib/python3.7/site-packages/pymysql/connections.py", line 732, in _read_query_result
    result.read()
  File "/Library/Frameworks/Python.framework/Versions/3.7/lib/python3.7/site-packages/pymysql/connections.py", line 1075, in read
    first_packet = self.connection._read_packet()
  File "/Library/Frameworks/Python.framework/Versions/3.7/lib/python3.7/site-packages/pymysql/connections.py", line 684, in _read_packet
    packet.check_error()
  File "/Library/Frameworks/Python.framework/Versions/3.7/lib/python3.7/site-packages/pymysql/protocol.py", line 220, in check_error
    err.raise_mysql_exception(self._data)
  File "/Library/Frameworks/Python.framework/Versions/3.7/lib/python3.7/site-packages/pymysql/err.py", line 109, in raise_mysql_exception
    raise errorclass(errno, errval)
pymysql.err.InternalError: (1054, "Unknown column 'name' in 'field list'")

During handling of the above exception, another exception occurred:

Traceback (most recent call last):
  File "/Library/Frameworks/Python.framework/Versions/3.7/lib/python3.7/site-packages/twisted/internet/defer.py", line 654, in _runCallbacks
    current.result = callback(current.result, *args, **kw)
  File "/Library/Frameworks/Python.framework/Versions/3.7/lib/python3.7/site-packages/scrapy/utils/defer.py", line 154, in f
    return deferred_from_coro(coro_f(*coro_args, **coro_kwargs))
  File "/Users/zhangzhuoyu 1/homework/Python001-class01/week02/作业一/movies/movies/pipelines.py", line 55, in process_item
    self.logger.error(e)
AttributeError: 'MoviesPipeline' object has no attribute 'logger'
2020-07-06 22:36:46 [scrapy.core.scraper] ERROR: Error processing {'movie_name': '反贪风暴5', 'movie_time': '2019', 'movie_type': '动作／犯罪'}
Traceback (most recent call last):
  File "/Users/zhangzhuoyu 1/homework/Python001-class01/week02/作业一/movies/movies/pipelines.py", line 50, in process_item
    self.cursor.execute(sql)
  File "/Library/Frameworks/Python.framework/Versions/3.7/lib/python3.7/site-packages/pymysql/cursors.py", line 170, in execute
    result = self._query(query)
  File "/Library/Frameworks/Python.framework/Versions/3.7/lib/python3.7/site-packages/pymysql/cursors.py", line 328, in _query
    conn.query(q)
  File "/Library/Frameworks/Python.framework/Versions/3.7/lib/python3.7/site-packages/pymysql/connections.py", line 517, in query
    self._affected_rows = self._read_query_result(unbuffered=unbuffered)
  File "/Library/Frameworks/Python.framework/Versions/3.7/lib/python3.7/site-packages/pymysql/connections.py", line 732, in _read_query_result
    result.read()
  File "/Library/Frameworks/Python.framework/Versions/3.7/lib/python3.7/site-packages/pymysql/connections.py", line 1075, in read
    first_packet = self.connection._read_packet()
  File "/Library/Frameworks/Python.framework/Versions/3.7/lib/python3.7/site-packages/pymysql/connections.py", line 684, in _read_packet
    packet.check_error()
  File "/Library/Frameworks/Python.framework/Versions/3.7/lib/python3.7/site-packages/pymysql/protocol.py", line 220, in check_error
    err.raise_mysql_exception(self._data)
  File "/Library/Frameworks/Python.framework/Versions/3.7/lib/python3.7/site-packages/pymysql/err.py", line 109, in raise_mysql_exception
    raise errorclass(errno, errval)
pymysql.err.InternalError: (1054, "Unknown column 'name' in 'field list'")

During handling of the above exception, another exception occurred:

Traceback (most recent call last):
  File "/Library/Frameworks/Python.framework/Versions/3.7/lib/python3.7/site-packages/twisted/internet/defer.py", line 654, in _runCallbacks
    current.result = callback(current.result, *args, **kw)
  File "/Library/Frameworks/Python.framework/Versions/3.7/lib/python3.7/site-packages/scrapy/utils/defer.py", line 154, in f
    return deferred_from_coro(coro_f(*coro_args, **coro_kwargs))
  File "/Users/zhangzhuoyu 1/homework/Python001-class01/week02/作业一/movies/movies/pipelines.py", line 55, in process_item
    self.logger.error(e)
AttributeError: 'MoviesPipeline' object has no attribute 'logger'
2020-07-06 22:36:46 [scrapy.core.scraper] ERROR: Error processing {'movie_name': '囧妈', 'movie_time': '2020-01-25', 'movie_type': '剧情／喜剧'}
Traceback (most recent call last):
  File "/Users/zhangzhuoyu 1/homework/Python001-class01/week02/作业一/movies/movies/pipelines.py", line 50, in process_item
    self.cursor.execute(sql)
  File "/Library/Frameworks/Python.framework/Versions/3.7/lib/python3.7/site-packages/pymysql/cursors.py", line 170, in execute
    result = self._query(query)
  File "/Library/Frameworks/Python.framework/Versions/3.7/lib/python3.7/site-packages/pymysql/cursors.py", line 328, in _query
    conn.query(q)
  File "/Library/Frameworks/Python.framework/Versions/3.7/lib/python3.7/site-packages/pymysql/connections.py", line 517, in query
    self._affected_rows = self._read_query_result(unbuffered=unbuffered)
  File "/Library/Frameworks/Python.framework/Versions/3.7/lib/python3.7/site-packages/pymysql/connections.py", line 732, in _read_query_result
    result.read()
  File "/Library/Frameworks/Python.framework/Versions/3.7/lib/python3.7/site-packages/pymysql/connections.py", line 1075, in read
    first_packet = self.connection._read_packet()
  File "/Library/Frameworks/Python.framework/Versions/3.7/lib/python3.7/site-packages/pymysql/connections.py", line 684, in _read_packet
    packet.check_error()
  File "/Library/Frameworks/Python.framework/Versions/3.7/lib/python3.7/site-packages/pymysql/protocol.py", line 220, in check_error
    err.raise_mysql_exception(self._data)
  File "/Library/Frameworks/Python.framework/Versions/3.7/lib/python3.7/site-packages/pymysql/err.py", line 109, in raise_mysql_exception
    raise errorclass(errno, errval)
pymysql.err.InternalError: (1054, "Unknown column 'name' in 'field list'")

During handling of the above exception, another exception occurred:

Traceback (most recent call last):
  File "/Library/Frameworks/Python.framework/Versions/3.7/lib/python3.7/site-packages/twisted/internet/defer.py", line 654, in _runCallbacks
    current.result = callback(current.result, *args, **kw)
  File "/Library/Frameworks/Python.framework/Versions/3.7/lib/python3.7/site-packages/scrapy/utils/defer.py", line 154, in f
    return deferred_from_coro(coro_f(*coro_args, **coro_kwargs))
  File "/Users/zhangzhuoyu 1/homework/Python001-class01/week02/作业一/movies/movies/pipelines.py", line 55, in process_item
    self.logger.error(e)
AttributeError: 'MoviesPipeline' object has no attribute 'logger'
2020-07-06 22:36:46 [scrapy.core.scraper] ERROR: Error processing {'movie_name': '速度与激情：增压', 'movie_time': '2015-06-25', 'movie_type': '动作／短片'}
Traceback (most recent call last):
  File "/Users/zhangzhuoyu 1/homework/Python001-class01/week02/作业一/movies/movies/pipelines.py", line 50, in process_item
    self.cursor.execute(sql)
  File "/Library/Frameworks/Python.framework/Versions/3.7/lib/python3.7/site-packages/pymysql/cursors.py", line 170, in execute
    result = self._query(query)
  File "/Library/Frameworks/Python.framework/Versions/3.7/lib/python3.7/site-packages/pymysql/cursors.py", line 328, in _query
    conn.query(q)
  File "/Library/Frameworks/Python.framework/Versions/3.7/lib/python3.7/site-packages/pymysql/connections.py", line 517, in query
    self._affected_rows = self._read_query_result(unbuffered=unbuffered)
  File "/Library/Frameworks/Python.framework/Versions/3.7/lib/python3.7/site-packages/pymysql/connections.py", line 732, in _read_query_result
    result.read()
  File "/Library/Frameworks/Python.framework/Versions/3.7/lib/python3.7/site-packages/pymysql/connections.py", line 1075, in read
    first_packet = self.connection._read_packet()
  File "/Library/Frameworks/Python.framework/Versions/3.7/lib/python3.7/site-packages/pymysql/connections.py", line 684, in _read_packet
    packet.check_error()
  File "/Library/Frameworks/Python.framework/Versions/3.7/lib/python3.7/site-packages/pymysql/protocol.py", line 220, in check_error
    err.raise_mysql_exception(self._data)
  File "/Library/Frameworks/Python.framework/Versions/3.7/lib/python3.7/site-packages/pymysql/err.py", line 109, in raise_mysql_exception
    raise errorclass(errno, errval)
pymysql.err.InternalError: (1054, "Unknown column 'name' in 'field list'")

During handling of the above exception, another exception occurred:

Traceback (most recent call last):
  File "/Library/Frameworks/Python.framework/Versions/3.7/lib/python3.7/site-packages/twisted/internet/defer.py", line 654, in _runCallbacks
    current.result = callback(current.result, *args, **kw)
  File "/Library/Frameworks/Python.framework/Versions/3.7/lib/python3.7/site-packages/scrapy/utils/defer.py", line 154, in f
    return deferred_from_coro(coro_f(*coro_args, **coro_kwargs))
  File "/Users/zhangzhuoyu 1/homework/Python001-class01/week02/作业一/movies/movies/pipelines.py", line 55, in process_item
    self.logger.error(e)
AttributeError: 'MoviesPipeline' object has no attribute 'logger'
2020-07-06 22:36:46 [scrapy.core.engine] INFO: Closing spider (finished)
2020-07-06 22:36:46 [scrapy.statscollectors] INFO: Dumping Scrapy stats:
{'downloader/request_bytes': 495,
 'downloader/request_count': 1,
 'downloader/request_method_count/GET': 1,
 'downloader/response_bytes': 87617,
 'downloader/response_count': 1,
 'downloader/response_status_count/200': 1,
 'elapsed_time_seconds': 0.984139,
 'finish_reason': 'finished',
 'finish_time': datetime.datetime(2020, 7, 6, 14, 36, 46, 895313),
 'log_count/DEBUG': 1,
 'log_count/ERROR': 30,
 'log_count/INFO': 11,
 'memusage/max': 51933184,
 'memusage/startup': 51933184,
 'response_received_count': 1,
 'scheduler/dequeued': 1,
 'scheduler/dequeued/memory': 1,
 'scheduler/enqueued': 1,
 'scheduler/enqueued/memory': 1,
 'start_time': datetime.datetime(2020, 7, 6, 14, 36, 45, 911174)}
2020-07-06 22:36:46 [scrapy.core.engine] INFO: Spider closed (finished)
